Workbook

Sheet DATA
A1: 번호 | B1: 센터 코드 | C1: 센터명 | D1: 상품 코드 | E1: 상품명 | F1: 납품원가 | G1: 납품예정일자 | H1: 납품예정시간 | I1: 센터별 입고 추천시간 | J1: 수정일자 | K1: 수정시간 | L1: 총수량 | M1: 수정수량 | N1: 발주단위수량 | O1: 발주단위 | P1: 수정배수 | Q1: 규격 | R1: 미납/일자변경사유 | S1: 소비(유통)기한 관리여부 | T1: 소비(유통)기한표시방식 | U1: 소비(유통) 기한 | V1: 제조 일자 | W1: 혼재 여부 | X1: 운송 수단 | Y1: 차량 번호 | Z1: 택배사 | AA1: 운송자 번호 | AB1: 상품그룹 | AC1: 모바일운영구분 | AD1: 최근입고소비(유통)기한 | AE1: 처리 상태 | AF1: BGF 발주 상태
B2: 990 | C2: 진천CDC | D2: 8809020343744 | E2: 멘소)아크네스스팟패치 | F2: 1364 | G2: 20260325110000 | H2: 20260325110000 | J2: 20260325110000 | K2: 20260325110000 | L2: 80 | M2: 80 | N2: 40 | O2: 박스 | P2: 2 | Q2: 14 | R2: 정상 | S2: 네 | T2: 생산 일자(제조일) | W2: 아니오 | AB2: 공산품 | AC2: OFF_LINE | AD2: 20281109150000 | AE2: 확정 | AF2: 확정
B3: 990 | C3: 진천CDC | D3: 8809020345212 | E3: 멘소래담)스프레이쿨타입 | F3: 2303 | G3: 20260325110000 | H3: 20260325110000 | J3: 20260325110000 | K3: 20260325110000 | L3: 432 | M3: 432 | N3: 16 | O3: 박스 | P3: 27 | Q3: 184 | R3: 정상 | S3: 네 | T3: 생산 일자(제조일) | W3: 아니오 | AB3: 공산품 | AC3: OFF_LINE | AD3: 20280831000000 | AE3: 확정 | AF3: 확정

Sheet 서식파일(수주업로드)
A1: 납품일자 | B1: 점포명 | C1: 점포코드 | D1: 점포명 | E1: 배송코드 | F1: 바코드 | G1: MECODE | H1: 상품명 | I1: 수량 | J1: 발주원가 | K1: 발주금액 | M1: 유통기한 | N1: 잔여일수 | O1: 유통일수 | P1: %
A2: =DATA!G2 -> 20260325110000 | B2: =DATA!C2 -> 진천CDC | C2: =VLOOKUP(B2,점포명!B:C,2,0) -> 82032027 | D2: =DATA!C2 -> 진천CDC | E2: =VLOOKUP(D2,점포명!B:C,2,0) -> 82032027 | F2: =DATA!D2 -> 8809020343744 | G2: =VLOOKUP(F2,제품코드!A:C,2,0) -> ME00621CCP | H2: =DATA!E2 -> 멘소)아크네스스팟패치 | I2: =DATA!L2 -> 80 | J2: =VLOOKUP(G2,제품코드!B:D,3,0) -> 1364 | K2: =I2*J2 -> 109120 | N2: =M2-TODAY() -> -46105 | O2: =365*3 -> 1095 | P2: =N2/O2 -> -42.105023
A3: =DATA!G3 -> 20260325110000 | B3: =DATA!C3 -> 진천CDC | C3: =VLOOKUP(B3,점포명!B:C,2,0) -> 82032027 | D3: =DATA!C3 -> 진천CDC | E3: =VLOOKUP(D3,점포명!B:C,2,0) -> 82032027 | F3: =DATA!D3 -> 8809020345212 | G3: =VLOOKUP(F3,제품코드!A:C,2,0) -> ME00421185 | H3: =DATA!E3 -> 멘소래담)스프레이쿨타입 | I3: =DATA!L3 -> 432 | J3: =VLOOKUP(G3,제품코드!B:D,3,0) -> 2303 | K3: =I3*J3 -> 994896 | N3: =M3-TODAY() -> -46105 | O3: =365*3 -> 1095 | P3: =N3/O3 -> -42.105023
A4: =DATA!G4 -> 0 | B4: =DATA!C4 -> 0 | C4: =VLOOKUP(B4,점포명!B:C,2,0) -> #N/A | D4: =DATA!C4 -> 0 | E4: =VLOOKUP(D4,점포명!B:C,2,0) -> #N/A | F4: =DATA!D4 -> 0 | G4: =VLOOKUP(F4,제품코드!A:C,2,0) -> #N/A | H4: =DATA!E4 -> 0 | I4: =DATA!L4 -> 0 | J4: =VLOOKUP(G4,제품코드!B:D,3,0) -> #N/A | K4: =I4*J4 -> #N/A | N4: =M4-TODAY() -> -46105 | O4: =365*3 -> 1095 | P4: =N4/O4 -> -42.105023
A5: =DATA!G5 -> 0 | B5: =DATA!C5 -> 0 | C5: =VLOOKUP(B5,점포명!B:C,2,0) -> #N/A | D5: =DATA!C5 -> 0 | E5: =VLOOKUP(D5,점포명!B:C,2,0) -> #N/A | F5: =DATA!D5 -> 0 | G5: =VLOOKUP(F5,제품코드!A:C,2,0) -> #N/A | H5: =DATA!E5 -> 0 | I5: =DATA!L5 -> 0 | J5: =VLOOKUP(G5,제품코드!B:D,3,0) -> #N/A | K5: =I5*J5 -> #N/A | N5: =M5-TODAY() -> -46105 | O5: =365*3 -> 1095 | P5: =N5/O5 -> -42.105023
A6: =DATA!G6 -> 0 | B6: =DATA!C6 -> 0 | C6: =VLOOKUP(B6,점포명!B:C,2,0) -> #N/A | D6: =DATA!C6 -> 0 | E6: =VLOOKUP(D6,점포명!B:C,2,0) -> #N/A | F6: =DATA!D6 -> 0 | G6: =VLOOKUP(F6,제품코드!A:C,2,0) -> #N/A | H6: =DATA!E6 -> 0 | I6: =DATA!L6 -> 0 | J6: =VLOOKUP(G6,제품코드!B:D,3,0) -> #N/A | K6: =I6*J6 -> #N/A
A7: =DATA!E7 -> 0 | B7: =DATA!B7 -> 0 | C7: =VLOOKUP(B7,점포명!B:C,2,0) -> #N/A | D7: =DATA!C7 -> 0 | E7: =VLOOKUP(D7,점포명!B:C,2,0) -> #N/A | F7: =DATA!C7 -> 0 | G7: =VLOOKUP(F7,제품코드!A:C,2,0) -> #N/A | H7: =DATA!D7 -> 0 | I7: =DATA!L7 -> 0 | J7: =VLOOKUP(G7,제품코드!B:D,3,0) -> #N/A | K7: =I7*J7 -> #N/A
A8: =DATA!E8 -> 0 | B8: =DATA!B8 -> 0 | C8: =VLOOKUP(B8,점포명!B:C,2,0) -> #N/A | D8: =DATA!C8 -> 0 | E8: =VLOOKUP(D8,점포명!B:C,2,0) -> #N/A | F8: =DATA!C8 -> 0 | G8: =VLOOKUP(F8,제품코드!A:C,2,0) -> #N/A | H8: =DATA!D8 -> 0 | I8: =DATA!L8 -> 0 | J8: =VLOOKUP(G8,제품코드!B:D,3,0) -> #N/A | K8: =I8*J8 -> #N/A
A9: =DATA!E9 -> 0 | B9: =DATA!B9 -> 0 | C9: =VLOOKUP(B9,점포명!B:C,2,0) -> #N/A | D9: =DATA!C9 -> 0 | E9: =VLOOKUP(D9,점포명!B:C,2,0) -> #N/A | F9: =DATA!C9 -> 0 | G9: =VLOOKUP(F9,제품코드!A:C,2,0) -> #N/A | H9: =DATA!D9 -> 0 | I9: =DATA!L9 -> 0 | J9: =VLOOKUP(G9,제품코드!B:D,3,0) -> #N/A | K9: =I9*J9 -> #N/A | M9: 납품기준 | N9: 납품 기준 미달 이슈 있을 시 담당 영업사원에게 필히 공유
A10: =DATA!E10 -> 0 | B10: =DATA!B10 -> 0 | C10: =VLOOKUP(B10,점포명!B:C,2,0) -> #N/A | D10: =DATA!C10 -> 0 | E10: =VLOOKUP(D10,점포명!B:C,2,0) -> #N/A | F10: =DATA!C10 -> 0 | G10: =VLOOKUP(F10,제품코드!A:C,2,0) -> #N/A | H10: =DATA!D10 -> 0 | I10: =DATA!L10 -> 0 | J10: =VLOOKUP(G10,제품코드!B:D,3,0) -> #N/A | K10: =I10*J10 -> #N/A | M10: 80%까지 입고 가능
A11: =DATA!E11 -> 0 | B11: =DATA!B11 -> 0 | C11: =VLOOKUP(B11,점포명!B:C,2,0) -> #N/A | D11: =DATA!C11 -> 0 | E11: =VLOOKUP(D11,점포명!B:C,2,0) -> #N/A | F11: =DATA!C11 -> 0 | G11: =VLOOKUP(F11,제품코드!A:C,2,0) -> #N/A | H11: =DATA!D11 -> 0 | I11: =DATA!L11 -> 0 | J11: =VLOOKUP(G11,제품코드!B:D,3,0) -> #N/A | K11: =I11*J11 -> #N/A | M11: 유통기한 역순 입고 시 인수 거절 사유
A12: =DATA!E12 -> 0 | B12: =DATA!B12 -> 0 | C12: =VLOOKUP(B12,점포명!B:C,2,0) -> #N/A | D12: =DATA!C12 -> 0 | E12: =VLOOKUP(D12,점포명!B:C,2,0) -> #N/A | F12: =DATA!C12 -> 0 | G12: =VLOOKUP(F12,제품코드!A:C,2,0) -> #N/A | H12: =DATA!D12 -> 0 | I12: =DATA!L12 -> 0 | J12: =VLOOKUP(G12,제품코드!B:D,3,0) -> #N/A | K12: =I12*J12 -> #N/A | M12: 예를들어 25-12-13 상품 납품 후 25-12-10 상품 납품 될 경우 인수 거부할 수 있음
A13: =DATA!E13 -> 0 | B13: =DATA!B13 -> 0 | C13: =VLOOKUP(B13,점포명!B:C,2,0) -> #N/A | D13: =DATA!C13 -> 0 | E13: =VLOOKUP(D13,점포명!B:C,2,0) -> #N/A | F13: =DATA!C13 -> 0 | G13: =VLOOKUP(F13,제품코드!A:C,2,0) -> #N/A | H13: =DATA!D13 -> 0 | I13: =DATA!L13 -> 0 | J13: =VLOOKUP(G13,제품코드!B:D,3,0) -> #N/A | K13: =I13*J13 -> #N/A
A14: =DATA!E14 -> 0 | B14: =DATA!B14 -> 0 | C14: =VLOOKUP(B14,점포명!B:C,2,0) -> #N/A | D14: =DATA!C14 -> 0 | E14: =VLOOKUP(D14,점포명!B:C,2,0) -> #N/A | F14: =DATA!C14 -> 0 | G14: =VLOOKUP(F14,제품코드!A:C,2,0) -> #N/A | H14: =DATA!D14 -> 0 | I14: =DATA!L14 -> 0 | J14: =VLOOKUP(G14,제품코드!B:D,3,0) -> #N/A | K14: =I14*J14 -> #N/A
A15: =DATA!E15 -> 0 | B15: =DATA!B15 -> 0 | C15: =VLOOKUP(B15,점포명!B:C,2,0) -> #N/A | D15: =DATA!C15 -> 0 | E15: =VLOOKUP(D15,점포명!B:C,2,0) -> #N/A | F15: =DATA!C15 -> 0 | G15: =VLOOKUP(F15,제품코드!A:C,2,0) -> #N/A | H15: =DATA!D15 -> 0 | I15: =DATA!L15 -> 0 | J15: =VLOOKUP(G15,제품코드!B:D,3,0) -> #N/A | K15: =I15*J15 -> #N/A
A16: =DATA!E16 -> 0 | B16: =DATA!B16 -> 0 | C16: =VLOOKUP(B16,점포명!B:C,2,0) -> #N/A | D16: =DATA!B16 -> 0 | E16: =VLOOKUP(D16,점포명!B:C,2,0) -> #N/A | F16: =DATA!C16 -> 0 | G16: =VLOOKUP(F16,제품코드!A:C,2,0) -> #N/A | H16: =DATA!D16 -> 0 | I16: =DATA!L16 -> 0 | J16: =VLOOKUP(G16,제품코드!B:D,3,0) -> #N/A | K16: =I16*J16 -> #N/A
A17: =DATA!E17 -> 0 | B17: =DATA!B17 -> 0 | C17: =VLOOKUP(B17,점포명!B:C,2,0) -> #N/A | D17: =DATA!B17 -> 0 | E17: =VLOOKUP(D17,점포명!B:C,2,0) -> #N/A | F17: =DATA!C17 -> 0 | G17: =VLOOKUP(F17,제품코드!A:C,2,0) -> #N/A | H17: =DATA!D17 -> 0 | I17: =DATA!L17 -> 0 | J17: =VLOOKUP(G17,제품코드!B:D,3,0) -> #N/A | K17: =I17*J17 -> #N/A
A18: =DATA!E18 -> 0 | B18: =DATA!B18 -> 0 | C18: =VLOOKUP(B18,점포명!B:C,2,0) -> #N/A | D18: =DATA!B18 -> 0 | E18: =VLOOKUP(D18,점포명!B:C,2,0) -> #N/A | F18: =DATA!C18 -> 0 | G18: =VLOOKUP(F18,제품코드!A:C,2,0) -> #N/A | H18: =DATA!D18 -> 0 | I18: =DATA!L18 -> 0 | J18: =VLOOKUP(G18,제품코드!B:D,3,0) -> #N/A | K18: =I18*J18 -> #N/A
A19: =DATA!E19 -> 0 | B19: =DATA!B19 -> 0 | C19: =VLOOKUP(B19,점포명!B:C,2,0) -> #N/A | D19: =DATA!B19 -> 0 | E19: =VLOOKUP(D19,점포명!B:C,2,0) -> #N/A | F19: =DATA!C19 -> 0 | G19: =VLOOKUP(F19,제품코드!A:C,2,0) -> #N/A | H19: =DATA!D19 -> 0 | I19: =DATA!L19 -> 0 | J19: =VLOOKUP(G19,제품코드!B:D,3,0) -> #N/A | K19: =I19*J19 -> #N/A
A20: =DATA!E20 -> 0 | B20: =DATA!B20 -> 0 | C20: =VLOOKUP(B20,점포명!B:C,2,0) -> #N/A | D20: =DATA!B20 -> 0 | E20: =VLOOKUP(D20,점포명!B:C,2,0) -> #N/A | F20: =DATA!C20 -> 0 | G20: =VLOOKUP(F20,제품코드!A:C,2,0) -> #N/A | H20: =DATA!D20 -> 0 | I20: =DATA!L20 -> 0 | J20: =VLOOKUP(G20,제품코드!B:D,3,0) -> #N/A | K20: =I20*J20 -> #N/A
B21: =DATA!B21 -> 0 | C21: =VLOOKUP(B21,점포명!B:C,2,0) -> #N/A | D21: =DATA!B21 -> 0 | E21: =VLOOKUP(D21,점포명!B:C,2,0) -> #N/A | F21: =DATA!C21 -> 0 | G21: =VLOOKUP(F21,제품코드!A:C,2,0) -> #N/A | H21: =DATA!D21 -> 0 | I21: =DATA!L21 -> 0 | J21: =VLOOKUP(G21,제품코드!B:D,3,0) -> #N/A | K21: =I21*J21 -> #N/A
B22: =DATA!B22 -> 0 | C22: =VLOOKUP(B22,점포명!B:C,2,0) -> #N/A | D22: =DATA!B22 -> 0 | E22: =VLOOKUP(D22,점포명!B:C,2,0) -> #N/A | F22: =DATA!C22 -> 0 | G22: =VLOOKUP(F22,제품코드!A:C,2,0) -> #N/A | H22: =DATA!D22 -> 0 | I22: =DATA!L22 -> 0 | J22: =VLOOKUP(G22,제품코드!B:D,3,0) -> #N/A | K22: =I22*J22 -> #N/A
B23: =DATA!B23 -> 0 | C23: =VLOOKUP(B23,점포명!B:C,2,0) -> #N/A | D23: =DATA!B23 -> 0 | E23: =VLOOKUP(D23,점포명!B:C,2,0) -> #N/A | F23: =DATA!C23 -> 0 | G23: =VLOOKUP(F23,제품코드!A:C,2,0) -> #N/A | H23: =DATA!D23 -> 0 | I23: =DATA!L23 -> 0 | J23: =VLOOKUP(G23,제품코드!B:D,3,0) -> #N/A | K23: =I23*J23 -> #N/A
B24: =DATA!B24 -> 0 | C24: =VLOOKUP(B24,점포명!B:C,2,0) -> #N/A | D24: =DATA!B24 -> 0 | E24: =VLOOKUP(D24,점포명!B:C,2,0) -> #N/A | F24: =DATA!C24 -> 0 | G24: =VLOOKUP(F24,제품코드!A:C,2,0) -> #N/A | H24: =DATA!D24 -> 0 | I24: =DATA!L24 -> 0 | J24: =VLOOKUP(G24,제품코드!B:D,3,0) -> #N/A | K24: =I24*J24 -> #N/A
B25: =DATA!B25 -> 0 | C25: =VLOOKUP(B25,점포명!B:C,2,0) -> #N/A | D25: =DATA!B25 -> 0 | E25: =VLOOKUP(D25,점포명!B:C,2,0) -> #N/A | F25: =DATA!C25 -> 0 | G25: =VLOOKUP(F25,제품코드!A:C,2,0) -> #N/A | H25: =DATA!D25 -> 0 | I25: =DATA!L25 -> 0 | J25: =VLOOKUP(G25,제품코드!B:D,3,0) -> #N/A | K25: =I25*J25 -> #N/A
B26: =DATA!B26 -> 0 | C26: =VLOOKUP(B26,점포명!B:C,2,0) -> #N/A | D26: =DATA!B26 -> 0 | E26: =VLOOKUP(D26,점포명!B:C,2,0) -> #N/A | F26: =DATA!C26 -> 0 | G26: =VLOOKUP(F26,제품코드!A:C,2,0) -> #N/A | H26: =DATA!D26 -> 0 | I26: =DATA!L26 -> 0 | J26: =VLOOKUP(G26,제품코드!B:D,3,0) -> #N/A | K26: =I26*J26 -> #N/A
B27: =DATA!B27 -> 0 | C27: =VLOOKUP(B27,점포명!B:C,2,0) -> #N/A | D27: =DATA!B27 -> 0 | E27: =VLOOKUP(D27,점포명!B:C,2,0) -> #N/A | F27: =DATA!C27 -> 0 | G27: =VLOOKUP(F27,제품코드!A:C,2,0) -> #N/A | H27: =DATA!D27 -> 0 | I27: =DATA!L27 -> 0 | J27: =VLOOKUP(G27,제품코드!B:D,3,0) -> #N/A | K27: =I27*J27 -> #N/A
B28: =DATA!B28 -> 0 | C28: =VLOOKUP(B28,점포명!B:C,2,0) -> #N/A | D28: =DATA!B28 -> 0 | E28: =VLOOKUP(D28,점포명!B:C,2,0) -> #N/A | F28: =DATA!C28 -> 0 | G28: =VLOOKUP(F28,제품코드!A:C,2,0) -> #N/A | H28: =DATA!D28 -> 0 | I28: =DATA!L28 -> 0 | J28: =VLOOKUP(G28,제품코드!B:D,3,0) -> #N/A | K28: =I28*J28 -> #N/A
B29: =DATA!B29 -> 0 | C29: =VLOOKUP(B29,점포명!B:C,2,0) -> #N/A | D29: =DATA!B29 -> 0 | E29: =VLOOKUP(D29,점포명!B:C,2,0) -> #N/A | F29: =DATA!C29 -> 0 | G29: =VLOOKUP(F29,제품코드!A:C,2,0) -> #N/A | H29: =DATA!D29 -> 0 | I29: =DATA!L29 -> 0 | J29: =VLOOKUP(G29,제품코드!B:D,3,0) -> #N/A | K29: =I29*J29 -> #N/A
B30: =DATA!B30 -> 0 | C30: =VLOOKUP(B30,점포명!B:C,2,0) -> #N/A | D30: =DATA!B30 -> 0 | E30: =VLOOKUP(D30,점포명!B:C,2,0) -> #N/A | F30: =DATA!C30 -> 0 | G30: =VLOOKUP(F30,제품코드!A:C,2,0) -> #N/A | H30: =DATA!D30 -> 0 | I30: =DATA!L30 -> 0 | J30: =VLOOKUP(G30,제품코드!B:D,3,0) -> #N/A | K30: =I30*J30 -> #N/A
B31: =DATA!B31 -> 0 | C31: =VLOOKUP(B31,점포명!B:C,2,0) -> #N/A | D31: =DATA!B31 -> 0 | E31: =VLOOKUP(D31,점포명!B:C,2,0) -> #N/A | F31: =DATA!C31 -> 0 | G31: =VLOOKUP(F31,제품코드!A:C,2,0) -> #N/A | H31: =DATA!D31 -> 0 | I31: =DATA!L31 -> 0 | J31: =VLOOKUP(G31,제품코드!B:D,3,0) -> #N/A | K31: =I31*J31 -> #N/A
B32: =DATA!B32 -> 0 | C32: =VLOOKUP(B32,점포명!B:C,2,0) -> #N/A | D32: =DATA!B32 -> 0 | E32: =VLOOKUP(D32,점포명!B:C,2,0) -> #N/A | F32: =DATA!C32 -> 0 | G32: =VLOOKUP(F32,제품코드!A:C,2,0) -> #N/A | H32: =DATA!D32 -> 0 | I32: =DATA!L32 -> 0 | J32: =VLOOKUP(G32,제품코드!B:D,3,0) -> #N/A | K32: =I32*J32 -> #N/A
... B48: =DATA!B48 -> 0 | C48: =VLOOKUP(B48,점포명!B:C,2,0) -> #N/A | D48: =DATA!B48 -> 0 | E48: =VLOOKUP(D48,점포명!B:C,2,0) -> #N/A | F48: =DATA!C48 -> 0 | G48: =VLOOKUP(F48,제품코드!A:C,2,0) -> #N/A | H48: =DATA!D48 -> 0 | I48: =DATA!L48 -> 0 | J48: =VLOOKUP(G48,제품코드!B:D,3,0) -> #N/A | K48: =I48*J48 -> #N/A
B49: =DATA!B49 -> 0 | C49: =VLOOKUP(B49,점포명!B:C,2,0) -> #N/A | D49: =DATA!B49 -> 0 | E49: =VLOOKUP(D49,점포명!B:C,2,0) -> #N/A | F49: =DATA!C49 -> 0 | G49: =VLOOKUP(F49,제품코드!A:C,2,0) -> #N/A | I49: =DATA!L49 -> 0 | J49: =VLOOKUP(G49,제품코드!B:D,3,0) -> #N/A | K49: =I49*J49 -> #N/A
B50: =DATA!B50 -> 0 | C50: =VLOOKUP(B50,점포명!B:C,2,0) -> #N/A | D50: =DATA!B50 -> 0 | E50: =VLOOKUP(D50,점포명!B:C,2,0) -> #N/A | F50: =DATA!C50 -> 0 | G50: =VLOOKUP(F50,제품코드!A:C,2,0) -> #N/A | I50: =DATA!L50 -> 0 | J50: =VLOOKUP(G50,제품코드!B:D,3,0) -> #N/A | K50: =I50*J50 -> #N/A
B51: =DATA!B51 -> 0 | C51: =VLOOKUP(B51,점포명!B:C,2,0) -> #N/A | D51: =DATA!B51 -> 0 | E51: =VLOOKUP(D51,점포명!B:C,2,0) -> #N/A | F51: =DATA!C51 -> 0 | G51: =VLOOKUP(F51,제품코드!A:C,2,0) -> #N/A | I51: =DATA!L51 -> 0 | J51: =VLOOKUP(G51,제품코드!B:D,3,0) -> #N/A | K51: =I51*J51 -> #N/A
B52: =DATA!B52 -> 0 | C52: =VLOOKUP(B52,점포명!B:C,2,0) -> #N/A | D52: =DATA!B52 -> 0 | E52: =VLOOKUP(D52,점포명!B:C,2,0) -> #N/A | F52: =DATA!C52 -> 0 | G52: =VLOOKUP(F52,제품코드!A:C,2,0) -> #N/A | I52: =DATA!L52 -> 0 | J52: =VLOOKUP(G52,제품코드!B:D,3,0) -> #N/A | K52: =I52*J52 -> #N/A
B53: =DATA!B53 -> 0 | C53: =VLOOKUP(B53,점포명!B:C,2,0) -> #N/A | D53: =DATA!B53 -> 0 | E53: =VLOOKUP(D53,점포명!B:C,2,0) -> #N/A | F53: =DATA!C53 -> 0 | G53: =VLOOKUP(F53,제품코드!A:C,2,0) -> #N/A | I53: =DATA!L53 -> 0 | J53: =VLOOKUP(G53,제품코드!B:D,3,0) -> #N/A | K53: =I53*J53 -> #N/A
B54: =DATA!B54 -> 0 | C54: =VLOOKUP(B54,점포명!B:C,2,0) -> #N/A | D54: =DATA!B54 -> 0 | E54: =VLOOKUP(D54,점포명!B:C,2,0) -> #N/A | F54: =DATA!C54 -> 0 | G54: =VLOOKUP(F54,제품코드!A:C,2,0) -> #N/A | I54: =DATA!L54 -> 0 | J54: =VLOOKUP(G54,제품코드!B:D,3,0) -> #N/A | K54: =I54*J54 -> #N/A
B55: =DATA!B55 -> 0 | C55: =VLOOKUP(B55,점포명!B:C,2,0) -> #N/A | D55: =DATA!B55 -> 0 | E55: =VLOOKUP(D55,점포명!B:C,2,0) -> #N/A | F55: =DATA!C55 -> 0 | G55: =VLOOKUP(F55,제품코드!A:C,2,0) -> #N/A | I55: =DATA!L55 -> 0 | J55: =VLOOKUP(G55,제품코드!B:D,3,0) -> #N/A | K55: =I55*J55 -> #N/A
...

Sheet 제품코드
A1: 바코드 | B1: 제품코드 | C1: 상품명 | D1: 원가 | E1: 행사가
A2: 8809020345212 | B2: ME00421185 | C2: 멘소래담)스프레이쿨타입 | D2: 2303
A3: 8809020342419 | B3: ME90521LXS | C3: 립아이스 딸기 X 라인 (48입) | D3: 2073
A4: 8809020342211 | B4: ME90521LXL | C4: 립아이스 레몬 X 라인 (48입 | D4: 2073
A5: 8809020341207 | B5: ME80421DR3 | C5: 멘소래담)온열마사지로션 | D5: 4950
A6: 8809020345229 | B6: ME00421300 | C6: 익스트림 스프레이180ml(핫타입-빨간색캔) | D6: 2550
A7: 8809020343744 | B7: ME00621CCP | C7: 멘소)아크네스스팟패치 | D7: 1364
A8: 8809020344567 | B8: ME00621PCG | C8: 멘소)아크네스폼클렌저 | D8: 2316

Sheet 점포명
B1: 점포명 | C1: 점포코드
A2: 서울로지스 | B2: BGF로지스용인 | C2: 82032001
A3: 경인로지스 | B3: BGF로지스강화 | C3: 82032002
A4: 영남로지스 | B4: BGF로지스울산 | C4: 82032009
A5: 보광로지스 | B5: BGF로지스양주 | C5: 82032003
A6: 제주로지스 | B6: BGF로지스제주 | C6: 82032010
A7: 하이로지스 | B7: 하이로지스 | C7: 82032008
A8: 대구로지스 | B8: BGF로지스대구 | C8: 82032012
A9: 중부로지스 | B9: BGF로지스화성 | C9: 82032004
A10: 동부로지스 | B10: 동부로지스 | C10: 82032007
A11: 극동로지스 | B11: 극동로지스
A12: 엑소후레쉬일산 | B12: 엑소후레쉬일산
A13: 아신 | B13: 아신
A14: 화인훼미리 | B14: 화인훼미리
A15: 동광로지스 | B15: 동광
A16: 화인로지텍 | B16: 화인로지텍 | C16: 82032005
A17: 안성로지스 | B17: BGF로지스안성 | C17: 82032013
A18: 나주로지스 | B18: BGF로지스나주 | C18: 82032014
A19: 진주로지스 | B19: BGF로지스진주 | C19: 82032015
A20: 수지로지스 | B20: BGF로지스수지 | C20: 82032016
A21: 엑소후레쉬신갈 | B21: 엑소후레쉬일산
A22: 안성잡화 | B22: BGF로지스안성잡화
A23: 강릉로지스 | B23: BGF로지스강릉 | C23: 82032017
A24: 진주잡화 | B24: BGF로지스진주잡화
A25: 양산로지스 | B25: BGF 리테일 양산센터 | C25: 82032019
A26: BGF로지스양산 | B26: BGF로지스양산 | C26: 82032019
A27: BGF로지스인천 | B27: BGF로지스인천 | C27: 82032020
A28: BGF로지스서귀포 | B28: BGF로지스서귀포 | C28: 82032021
A29: 김포물류 | B29: BGF로지스김포 | C29: 82032022
A30: 세종물류 | B30: BGF로지스세종 | C30: 82032023
A31: BGF로지스곤지암 | B31: BGF로지스곤지암 | C31: 82032024
A32: BGF로지스칠곡 | B32: BGF로지스칠곡 | C32: 82032025
B33: BGF로지스부천 | C33: 82032026
B34: 진천CDC | C34: 82032027
