Workbook
Name 지우기: '210311 (3)'!$A:$I
Name 지우기: #REF!

Sheet 210311 (3)
A1: 주문서 리스트 | J1: 점포명 | L1: 점포코드 | N1: ME00421185 | O1: 멘소래담 스프레이 쿨 180mL 16입 (New 2021) | P1: 16 | Q1: MC22-04 로 츨고
A2: 협력업체명 | B2: 맨소래덤아시아퍼시픽 주식회사 | E2: 작성일자 | F2: 2026-03-24 | J2: (주)코리아세븐 | L2: 81032000 | N2: bill to 고정
A3: 원가지준 : 단위 (원)
A5: 문서명 | B5: 문서번호 | C5: 주문구분 | D5: 송신자 | E5: 주문일 | F5: 점포(센터) | G5: 아이템갯수 | H5: 납품일 | I5: 센터입하일 | J5: 발주처코드 | L5: 배송코드 | M5: 배송지 | N5: 상품코드 | O5: 상품명 | P5: UNIT수량 | Q5: UNIT단가 | R5: 금 액
A6: ORDERS | B6: 2.0093203e+17 | C6: 통상 | D6: (주)코리아세븐 | E6: 2026-03-24 | F6: (주)코리아세븐 이천HUB(B)센터 | G6: 1 | H6: 2026-03-25 | I6: 2026-03-25 | J6: =$L$2 -> 81032000 | L6: =IFERROR(VLOOKUP(D6,마스터!$R$4:$S$40,2,0),"") | M6: =VLOOKUP(L6,마스터!S:T,2,0) -> #N/A | N6: =IFERROR(VLOOKUP(B6,마스터!$A$2:$B$8,2,0),"") | O6: =VLOOKUP(N6,마스터!$B$1:$G$8,2,0) -> #N/A | P6: =IFERROR(F6*G6,"") | Q6: =H6 -> 2026-03-25 | R6: =I6 -> 2026-03-25
A7: 상품코드 | B7: 판매코드 | C7: 상품명 | D7: 점포명 | E7: 규격 | F7: 입수 | G7: 주문수 | H7: 단가 | I7: 주문금액 | J7: =$L$2 -> 81032000 | L7: =IFERROR(VLOOKUP(D7,마스터!$R$4:$S$40,2,0),"") | M7: =VLOOKUP(L7,마스터!S:T,2,0) -> #N/A | N7: =IFERROR(VLOOKUP(B7,마스터!$A$2:$B$8,2,0),"") | O7: =VLOOKUP(N7,마스터!$B$1:$G$8,2,0) -> #N/A | P7: =IFERROR(F7*G7,"") | Q7: =H7 -> 단가 | R7: =I7 -> 주문금액
A8: 134550 | B8: 8809020343744 | C8: 아크네스)퍼펙트솔루션 스팟패치18매_H | D8: 20093((주)코리아세븐 이천HUB(B)센터) | E8: 1매 | F8: 40 | G8: 1 | H8: 1025 | I8: 41000 | J8: =$L$2 -> 81032000 | L8: =IFERROR(VLOOKUP(D8,마스터!$R$4:$S$80,2,0),"") -> 81010975 | M8: =VLOOKUP(L8,마스터!S:T,2,0) -> 20093((주)코리아세븐 이천HUB(B)센터) | N8: =IFERROR(VLOOKUP(B8,마스터!$A$2:$B$8,2,0),"") -> ME00621CCP | O8: =VLOOKUP(N8,마스터!$B$1:$G$8,2,0) -> 편의점용) 아크네스 퍼펙트 솔루션 스팟패치 18매 | P8: =IFERROR(F8*G8,"") -> 40 | Q8: =H8 -> 1025 | R8: =I8 -> 41000
A9: 합계 | G9: 1 | I9: 41000 | J9: =$L$2 -> 81032000 | L9: =IFERROR(VLOOKUP(D9,마스터!$R$4:$S$80,2,0),"") | M9: =VLOOKUP(L9,마스터!S:T,2,0) -> #N/A | N9: =IFERROR(VLOOKUP(B9,마스터!$A$2:$B$8,2,0),"") | O9: =VLOOKUP(N9,마스터!$B$1:$G$8,2,0) -> #N/A | P9: =IFERROR(F9*G9,"") -> 0 | Q9: =H9 -> 0 | R9: =I9 -> 41000
J10: =$L$2 -> 81032000 | L10: =IFERROR(VLOOKUP(D10,마스터!$R$4:$S$40,2,0),"") | M10: =VLOOKUP(L10,마스터!S:T,2,0) -> #N/A | N10: =IFERROR(VLOOKUP(B10,마스터!$A$2:$B$8,2,0),"") | O10: =VLOOKUP(N10,마스터!$B$1:$G$8,2,0) -> #N/A | P10: =IFERROR(F10*G10,"") -> 0 | Q10: =H10 -> 0 | R10: =I10 -> 0
J11: =$L$2 -> 81032000 | L11: =IFERROR(VLOOKUP(D11,마스터!$R$4:$S$40,2,0),"") | M11: =VLOOKUP(L11,마스터!S:T,2,0) -> #N/A | N11: =IFERROR(VLOOKUP(B11,마스터!$A$2:$B$8,2,0),"") | O11: =VLOOKUP(N11,마스터!$B$1:$G$8,2,0) -> #N/A | P11: =IFERROR(F11*G11,"") -> 0 | Q11: =H11 -> 0 | R11: =I11 -> 0
J12: =$L$2 -> 81032000 | L12: =IFERROR(VLOOKUP(D12,마스터!$R$4:$S$40,2,0),"") | M12: =VLOOKUP(L12,마스터!S:T,2,0) -> #N/A | N12: =IFERROR(VLOOKUP(B12,마스터!$A$2:$B$8,2,0),"") | O12: =VLOOKUP(N12,마스터!$B$1:$G$8,2,0) -> #N/A | P12: =IFERROR(F12*G12,"") -> 0 | Q12: =H12 -> 0 | R12: =I12 -> 0
J13: =$L$2 -> 81032000 | L13: =IFERROR(VLOOKUP(D13,마스터!$R$4:$S$40,2,0),"") | M13: =VLOOKUP(L13,마스터!S:T,2,0) -> #N/A | N13: =IFERROR(VLOOKUP(B13,마스터!$A$2:$B$8,2,0),"") | O13: =VLOOKUP(N13,마스터!$B$1:$G$8,2,0) -> #N/A | P13: =IFERROR(F13*G13,"") -> 0 | Q13: =H13 -> 0 | R13: =I13 -> 0
J14: =$L$2 -> 81032000 | L14: =IFERROR(VLOOKUP(D14,마스터!$R$4:$S$40,2,0),"") | M14: =VLOOKUP(L14,마스터!S:T,2,0) -> #N/A | N14: =IFERROR(VLOOKUP(B14,마스터!$A$2:$B$8,2,0),"") | O14: =VLOOKUP(N14,마스터!$B$1:$G$8,2,0) -> #N/A | P14: =IFERROR(F14*G14,"") -> 0 | Q14: =H14 -> 0 | R14: =I14 -> 0
J15: =$L$2 -> 81032000 | L15: =IFERROR(VLOOKUP(D15,마스터!$R$4:$S$80,2,0),"") | M15: =VLOOKUP(L15,마스터!S:T,2,0) -> #N/A | N15: =IFERROR(VLOOKUP(B15,마스터!$A$2:$B$8,2,0),"") | O15: =VLOOKUP(N15,마스터!$B$1:$G$8,2,0) -> #N/A | P15: =IFERROR(F15*G15,"") -> 0 | Q15: =H15 -> 0 | R15: =I15 -> 0
J16: =$L$2 -> 81032000 | L16: =IFERROR(VLOOKUP(D16,마스터!$R$4:$S$80,2,0),"") | M16: =VLOOKUP(L16,마스터!S:T,2,0) -> #N/A | N16: =IFERROR(VLOOKUP(B16,마스터!$A$2:$B$8,2,0),"") | O16: =VLOOKUP(N16,마스터!$B$1:$G$8,2,0) -> #N/A | P16: =IFERROR(F16*G16,"") -> 0 | Q16: =H16 -> 0 | R16: =I16 -> 0
J17: =$L$2 -> 81032000 | L17: =IFERROR(VLOOKUP(D17,마스터!$R$4:$S$80,2,0),"") | M17: =VLOOKUP(L17,마스터!S:T,2,0) -> #N/A | N17: =IFERROR(VLOOKUP(B17,마스터!$A$2:$B$8,2,0),"") | O17: =VLOOKUP(N17,마스터!$B$1:$G$8,2,0) -> #N/A | P17: =IFERROR(F17*G17,"") -> 0 | Q17: =H17 -> 0 | R17: =I17 -> 0
J18: =$L$2 -> 81032000 | L18: =IFERROR(VLOOKUP(D18,마스터!$R$4:$S$40,2,0),"") | M18: =VLOOKUP(L18,마스터!S:T,2,0) -> #N/A | N18: =IFERROR(VLOOKUP(B18,마스터!$A$2:$B$8,2,0),"") | O18: =VLOOKUP(N18,마스터!$B$1:$G$8,2,0) -> #N/A | P18: =IFERROR(F18*G18,"") -> 0 | Q18: =H18 -> 0 | R18: =I18 -> 0
J19: =$L$2 -> 81032000 | L19: =IFERROR(VLOOKUP(D19,마스터!$R$4:$S$40,2,0),"") | M19: =VLOOKUP(L19,마스터!S:T,2,0) -> #N/A | N19: =IFERROR(VLOOKUP(B19,마스터!$A$2:$B$8,2,0),"") | O19: =VLOOKUP(N19,마스터!$B$1:$G$8,2,0) -> #N/A | P19: =IFERROR(F19*G19,"") -> 0 | Q19: =H19 -> 0 | R19: =I19 -> 0
J20: =$L$2 -> 81032000 | L20: =IFERROR(VLOOKUP(D20,마스터!$R$4:$S$40,2,0),"") | M20: =VLOOKUP(L20,마스터!S:T,2,0) -> #N/A | N20: =IFERROR(VLOOKUP(B20,마스터!$A$2:$B$8,2,0),"") | O20: =VLOOKUP(N20,마스터!$B$1:$G$8,2,0) -> #N/A | P20: =IFERROR(F20*G20,"") -> 0 | Q20: =H20 -> 0 | R20: =I20 -> 0
J21: =$L$2 -> 81032000 | L21: =IFERROR(VLOOKUP(D21,마스터!$R$4:$S$40,2,0),"") | M21: =VLOOKUP(L21,마스터!S:T,2,0) -> #N/A | N21: =IFERROR(VLOOKUP(B21,마스터!$A$2:$B$8,2,0),"") | O21: =VLOOKUP(N21,마스터!$B$1:$G$8,2,0) -> #N/A | P21: =IFERROR(F21*G21,"") -> 0 | Q21: =H21 -> 0 | R21: =I21 -> 0
J22: =$L$2 -> 81032000 | L22: =IFERROR(VLOOKUP(D22,마스터!$R$4:$S$80,2,0),"") | M22: =VLOOKUP(L22,마스터!S:T,2,0) -> #N/A | N22: =IFERROR(VLOOKUP(B22,마스터!$A$2:$B$8,2,0),"") | O22: =VLOOKUP(N22,마스터!$B$1:$G$8,2,0) -> #N/A | P22: =IFERROR(F22*G22,"") -> 0 | Q22: =H22 -> 0 | R22: =I22 -> 0
J23: =$L$2 -> 81032000 | L23: =IFERROR(VLOOKUP(D23,마스터!$R$4:$S$80,2,0),"") | M23: =VLOOKUP(L23,마스터!S:T,2,0) -> #N/A | N23: =IFERROR(VLOOKUP(B23,마스터!$A$2:$B$8,2,0),"") | O23: =VLOOKUP(N23,마스터!$B$1:$G$8,2,0) -> #N/A | P23: =IFERROR(F23*G23,"") -> 0 | Q23: =H23 -> 0 | R23: =I23 -> 0
J24: =$L$2 -> 81032000 | L24: =IFERROR(VLOOKUP(D24,마스터!$R$4:$S$80,2,0),"") | M24: =VLOOKUP(L24,마스터!S:T,2,0) -> #N/A | N24: =IFERROR(VLOOKUP(B24,마스터!$A$2:$B$8,2,0),"") | O24: =VLOOKUP(N24,마스터!$B$1:$G$8,2,0) -> #N/A | P24: =IFERROR(F24*G24,"") -> 0 | Q24: =H24 -> 0 | R24: =I24 -> 0
J25: =$L$2 -> 81032000 | L25: =IFERROR(VLOOKUP(D25,마스터!$R$4:$S$80,2,0),"") | M25: =VLOOKUP(L25,마스터!S:T,2,0) -> #N/A | N25: =IFERROR(VLOOKUP(B25,마스터!$A$2:$B$8,2,0),"") | O25: =VLOOKUP(N25,마스터!$B$1:$G$8,2,0) -> #N/A | P25: =IFERROR(F25*G25,"") -> 0 | Q25: =H25 -> 0 | R25: =I25 -> 0
J26: =$L$2 -> 81032000 | L26: =IFERROR(VLOOKUP(D26,마스터!$R$4:$S$40,2,0),"") | M26: =VLOOKUP(L26,마스터!S:T,2,0) -> #N/A | N26: =IFERROR(VLOOKUP(B26,마스터!$A$2:$B$8,2,0),"") | O26: =VLOOKUP(N26,마스터!$B$1:$G$8,2,0) -> #N/A | P26: =IFERROR(F26*G26,"") -> 0 | Q26: =H26 -> 0 | R26: =I26 -> 0
J27: =$L$2 -> 81032000 | L27: =IFERROR(VLOOKUP(D27,마스터!$R$4:$S$40,2,0),"") | M27: =VLOOKUP(L27,마스터!S:T,2,0) -> #N/A | N27: =IFERROR(VLOOKUP(B27,마스터!$A$2:$B$8,2,0),"") | O27: =VLOOKUP(N27,마스터!$B$1:$G$8,2,0) -> #N/A | P27: =IFERROR(F27*G27,"") -> 0 | Q27: =H27 -> 0 | R27: =I27 -> 0
J28: =$L$2 -> 81032000 | L28: =IFERROR(VLOOKUP(D28,마스터!$R$4:$S$40,2,0),"") | M28: =VLOOKUP(L28,마스터!S:T,2,0) -> #N/A | N28: =IFERROR(VLOOKUP(B28,마스터!$A$2:$B$8,2,0),"") | O28: =VLOOKUP(N28,마스터!$B$1:$G$8,2,0) -> #N/A | P28: =IFERROR(F28*G28,"") -> 0 | Q28: =H28 -> 0 | R28: =I28 -> 0
J29: =$L$2 -> 81032000 | L29: =IFERROR(VLOOKUP(D29,마스터!$R$4:$S$80,2,0),"") | M29: =VLOOKUP(L29,마스터!S:T,2,0) -> #N/A | N29: =IFERROR(VLOOKUP(B29,마스터!$A$2:$B$8,2,0),"") | O29: =VLOOKUP(N29,마스터!$B$1:$G$8,2,0) -> #N/A | P29: =IFERROR(F29*G29,"") -> 0 | Q29: =H29 -> 0 | R29: =I29 -> 0
J30: =$L$2 -> 81032000 | L30: =IFERROR(VLOOKUP(D30,마스터!$R$4:$S$80,2,0),"") | M30: =VLOOKUP(L30,마스터!S:T,2,0) -> #N/A | N30: =IFERROR(VLOOKUP(B30,마스터!$A$2:$B$8,2,0),"") | O30: =VLOOKUP(N30,마스터!$B$1:$G$8,2,0) -> #N/A | P30: =IFERROR(F30*G30,"") -> 0 | Q30: =H30 -> 0 | R30: =I30 -> 0
J31: =$L$2 -> 81032000 | L31: =IFERROR(VLOOKUP(D31,마스터!$R$4:$S$80,2,0),"") | M31: =VLOOKUP(L31,마스터!S:T,2,0) -> #N/A | N31: =IFERROR(VLOOKUP(B31,마스터!$A$2:$B$8,2,0),"") | O31: =VLOOKUP(N31,마스터!$B$1:$G$8,2,0) -> #N/A | P31: =IFERROR(F31*G31,"") -> 0 | Q31: =H31 -> 0 | R31: =I31 -> 0
J32: =$L$2 -> 81032000 | L32: =IFERROR(VLOOKUP(D32,마스터!$R$4:$S$80,2,0),"") | M32: =VLOOKUP(L32,마스터!S:T,2,0) -> #N/A | N32: =IFERROR(VLOOKUP(B32,마스터!$A$2:$B$8,2,0),"") | O32: =VLOOKUP(N32,마스터!$B$1:$G$8,2,0) -> #N/A | P32: =IFERROR(F32*G32,"") -> 0 | Q32: =H32 -> 0 | R32: =I32 -> 0
J33: =$L$2 -> 81032000 | L33: =IFERROR(VLOOKUP(D33,마스터!$R$4:$S$80,2,0),"") | M33: =VLOOKUP(L33,마스터!S:T,2,0) -> #N/A | N33: =IFERROR(VLOOKUP(B33,마스터!$A$2:$B$8,2,0),"") | O33: =VLOOKUP(N33,마스터!$B$1:$G$8,2,0) -> #N/A | P33: =IFERROR(F33*G33,"") -> 0 | Q33: =H33 -> 0 | R33: =I33 -> 0
J34: =$L$2 -> 81032000 | L34: =IFERROR(VLOOKUP(D34,마스터!$R$4:$S$40,2,0),"") | M34: =VLOOKUP(L34,마스터!S:T,2,0) -> #N/A | N34: =IFERROR(VLOOKUP(B34,마스터!$A$2:$B$8,2,0),"") | O34: =VLOOKUP(N34,마스터!$B$1:$G$8,2,0) -> #N/A | P34: =IFERROR(F34*G34,"") -> 0 | Q34: =H34 -> 0 | R34: =I34 -> 0
J35: =$L$2 -> 81032000 | L35: =IFERROR(VLOOKUP(D35,마스터!$R$4:$S$40,2,0),"") | M35: =VLOOKUP(L35,마스터!S:T,2,0) -> #N/A | N35: =IFERROR(VLOOKUP(B35,마스터!$A$2:$B$8,2,0),"") | O35: =VLOOKUP(N35,마스터!$B$1:$G$8,2,0) -> #N/A | P35: =IFERROR(F35*G35,"") -> 0 | Q35: =H35 -> 0 | R35: =I35 -> 0
J36: =$L$2 -> 81032000 | L36: =IFERROR(VLOOKUP(D36,마스터!$R$4:$S$80,2,0),"") | M36: =VLOOKUP(L36,마스터!S:T,2,0) -> #N/A | N36: =IFERROR(VLOOKUP(B36,마스터!$A$2:$B$8,2,0),"") | O36: =VLOOKUP(N36,마스터!$B$1:$G$8,2,0) -> #N/A | P36: =IFERROR(F36*G36,"") -> 0 | Q36: =H36 -> 0 | R36: =I36 -> 0
J37: =$L$2 -> 81032000 | L37: =IFERROR(VLOOKUP(D37,마스터!$R$4:$S$80,2,0),"") | M37: =VLOOKUP(L37,마스터!S:T,2,0) -> #N/A | N37: =IFERROR(VLOOKUP(B37,마스터!$A$2:$B$8,2,0),"") | O37: =VLOOKUP(N37,마스터!$B$1:$G$8,2,0) -> #N/A | P37: =IFERROR(F37*G37,"") -> 0 | Q37: =H37 -> 0 | R37: =I37 -> 0
J38: =$L$2 -> 81032000 | L38: =IFERROR(VLOOKUP(D38,마스터!$R$4:$S$80,2,0),"") | M38: =VLOOKUP(L38,마스터!S:T,2,0) -> #N/A | N38: =IFERROR(VLOOKUP(B38,마스터!$A$2:$B$8,2,0),"") | O38: =VLOOKUP(N38,마스터!$B$1:$G$8,2,0) -> #N/A | P38: =IFERROR(F38*G38,"") -> 0 | Q38: =H38 -> 0 | R38: =I38 -> 0
J39: =$L$2 -> 81032000 | L39: =IFERROR(VLOOKUP(D39,마스터!$R$4:$S$80,2,0),"") | M39: =VLOOKUP(L39,마스터!S:T,2,0) -> #N/A | N39: =IFERROR(VLOOKUP(B39,마스터!$A$2:$B$8,2,0),"") | O39: =VLOOKUP(N39,마스터!$B$1:$G$8,2,0) -> #N/A | P39: =IFERROR(F39*G39,"") -> 0 | Q39: =H39 -> 0 | R39: =I39 -> 0
J40: =$L$2 -> 81032000 | L40: =IFERROR(VLOOKUP(D40,마스터!$R$4:$S$80,2,0),"") | M40: =VLOOKUP(L40,마스터!S:T,2,0) -> #N/A | N40: =IFERROR(VLOOKUP(B40,마스터!$A$2:$B$8,2,0),"") | O40: =VLOOKUP(N40,마스터!$B$1:$G$8,2,0) -> #N/A | P40: =IFERROR(F40*G40,"") -> 0 | Q40: =H40 -> 0 | R40: =I40 -> 0
J41: =$L$2 -> 81032000 | L41: =IFERROR(VLOOKUP(D41,마스터!$R$4:$S$80,2,0),"") | M41: =VLOOKUP(L41,마스터!S:T,2,0) -> #N/A | N41: =IFERROR(VLOOKUP(B41,마스터!$A$2:$B$8,2,0),"") | O41: =VLOOKUP(N41,마스터!$B$1:$G$8,2,0) -> #N/A | P41: =IFERROR(F41*G41,"") -> 0 | Q41: =H41 -> 0 | R41: =I41 -> 0
...

Sheet 마스터
A1: 바코드 | B1: 제품코드 | C1: 상품명 | D1: 상품단축명 | E1: 과세구분 | F1: 규격 | G1: 가로(mm) | H1: 세로(mm) | I1: 깊이(mm) | J1: 중량(g) | K1: 원산지코드 | L1: 원가 | M1: 매가 | N1: 발주단위 | O1: 입수 | P1: 브랜드명 | R1: 점포명 | S1: 점포코드
A2: 8809020345229 | B2: ME00421300 | C2: 스프레이 익스트림 | D2: 스프레이 익스트림 | E2: 과세 | F2: 180ml | G2: 53 | H2: 160 | I2: 53 | J2: 180g | K2: KR | L2: 2328 | M2: 4300 | N2: EA | O2: 1 | P2: 멘소래담 | R2: (주)코리아세븐 | S2: 81032000 | T2: bill to 고정
A3: 8809020345212 | B3: ME00421185 | C3: 스프레이 파스 | D3: 스프레이 파스 | E3: 과세 | F3: 180ml | G3: 53 | H3: 160 | I3: 53 | J3: 180g | K3: KR | L3: 2321 | M3: 3800 | N3: EA | O3: 1 | P3: 멘소래담
A4: 8809020348978 | B4: ME00421150 | C4: 맨소래담 딥앤쿨 스프레이 150ml*16입 | D4: 딥앤쿨 스프레이 | L4: 2780 | N4: EA | O4: 1 | P4: 멘소래담 | R4: 신갈센터 | S4: 81032901 | U4: 20004(양산물류)
A5: 8809020341207 | B5: ME80421DR3 | C5: 멘소)멘소래담롤온로션 | D5: 멘소래담 롤온로션 | L5: 4455 | N5: EA | R5: 20006(성남물류) | S5: 81032902 | T5: 20006(성남물류) | U5: 20006(성남물류)
A6: 8809020344048 | B6: ME90521L05 | C6: 멘소래담)메디케이티드 립밤 | D6: 메디케이티드 립밤 | R6: 20034(구성물류) | S6: 81032903 | T6: 20034(구성물류) | U6: 20006(성남물류)
A7: 8809020344574 | B7: ME00621PBN | C7: 아크네스 퍼펙트 솔루션 릴리프 바디 미스트 150ml (24입) | R7: 20019(광주상온센타) | S7: 81032904 | T7: 20019(광주상온센타) | U7: 20007(대구물류)
A8: 8809020343744 | B8: ME00621CCP | C8: 편의점용) 아크네스 퍼펙트 솔루션 스팟패치 18매 | R8: 20004(양산물류) | S8: 81032905 | T8: 20004(양산물류) | U8: 20010(양주물류)
R9: 20007(대구물류) | S9: 81032906 | T9: 20007(대구물류) | U9: 20017(언양상온센터(K7))
R10: 20010(양주물류) | S10: 81032907 | T10: 20010(양주물류) | U10: 20029(N경인화성상온센터(K7))
R11: 20033(제주상온센터) | S11: 81032908 | T11: 20033(제주상온센터) | U11: 20033(제주상온센터)
R12: 20049((주)코리아세븐 서이천상온센터) | S12: 81032918 | T12: 20049((주)코리아세븐 서이천상온센터) | U12: 20033(제주상온센터)
R13: 청원상온센터 | S13: 81032910 | T13: 청원상온센터 | U13: 20033(제주상온센터)
R14: 20017(언양상온센터(K7)) | S14: 81032911 | T14: 20017(언양상온센터(K7)) | U14: 20034(구성물류)
R15: 20029(N경인화성상온센터(K7)) | S15: 81032912 | T15: 20029(N경인화성상온센터(K7)) | U15: 20049(서이천상온센터)
R16: (주)코리아세븐 대전상온센터 | S16: 81032913 | T16: (주)코리아세븐 대전상온센터 | U16: 20049(서이천상온센터)
R17: 20065((주)코리아세븐 원주상온센터) | S17: 81032914 | T17: 20065((주)코리아세븐 원주상온센터) | U17: 20050(세종상온센터)
R18: (주)바이더웨이 일산센터 | S18: 82022901 | T18: (주)바이더웨이 일산센터 | U18: 20050(세종상온센터)
R19: (주)바이더웨이 중부센터 | S19: 82022902 | T19: (주)바이더웨이 중부센터 | U19: 20065((주)코리아세븐 원주상온센터)
R20: 20501((주)바이더웨이 경인센터) | S20: 82022903 | T20: 20501((주)바이더웨이 경인센터)
R21: (주)바이더웨이 언양센터 | S21: 82022904 | T21: (주)바이더웨이 언양센터
R22: (주)바이더웨이 잡화센터 | S22: 82022905 | T22: (주)바이더웨이 잡화센터
R23: (주)바이더웨이 광주센터 | S23: 82022906 | T23: (주)바이더웨이 광주센터
R24: (주)바이더웨이 원주센터 | S24: 82022907 | T24: (주)바이더웨이 원주센터
R25: 20050((주)코리아세븐 세종상온센터) | S25: 81032915 | T25: 20050((주)코리아세븐 세종상온센터)
R26: 20017(울산상온센터(K7)) | S26: 81032916 | T26: 20017(울산상온센터(K7))
R27: 20075((주)코리아세븐 인천상온센터) | S27: 81032917 | T27: 20075((주)코리아세븐 인천상온센터)
R28: 20075((주)코리아세븐 인천물류센터) | S28: 81032917 | T28: 20075((주)코리아세븐 인천물류센터)
R29: 20504((주)바이더웨이 울산상온센터) | S29: 81032916 | T29: 20504((주)바이더웨이 울산상온센터)
R30: 20503((주)바이더웨이 세종센터) | S30: 81032919 | T30: 20503((주)바이더웨이 세종센터)
R31: 20076((주)코리아세븐 의왕상온센터) | S31: 81032920 | T31: 20076((주)코리아세븐 의왕상온센터)
... R46: 20097((주)코리아세븐 청원HUB(C)센터) | S46: 81010978 | T46: 20097((주)코리아세븐 청원HUB(C)센터)
R47: 20092((주)코리아세븐 이천HUB(A)센터)
R48: 20033((주)코리아세븐 제주상온센터) | S48: 81032908 | T48: 20033(제주상온센터) | U48: 20033(제주상온센터)
R50: 20092((주)코리아세븐 이천HUB센터) | S50: 81010973 | T50: 20092((주)코리아세븐 이천HUB(A)센터)
R51: 20093((주)코리아세븐 이천HUB센터) | S51: 81010975 | T51: 20093((주)코리아세븐 이천HUB(B)센터)
R52: 20094((주)코리아세븐 이천HUB센터) | S52: 81010976 | T52: 20094((주)코리아세븐 이천HUB(C)센터)
R53: 20095((주)코리아세븐 청원HUB센터) | S53: 81010974 | T53: 20095((주)코리아세븐 청원HUB(A)센터)
R54: 20096((주)코리아세븐 청원HUB센터) | S54: 81010977 | T54: 20096((주)코리아세븐 청원HUB(B)센터)
R55: 20097((주)코리아세븐 청원HUB센터) | S55: 81010978 | T55: 20097((주)코리아세븐 청원HUB(C)센터)
